[2024-11-05T21:02:29.942+0000] {taskinstance.py:1159} INFO - Dependencies all met for dep_context=non-requeueable deps ti=<TaskInstance: initial_transform.hive_server_task manual__2024-11-05T21:02:25.593672+00:00 [queued]>
[2024-11-05T21:02:29.951+0000] {taskinstance.py:1159} INFO - Dependencies all met for dep_context=requeueable deps ti=<TaskInstance: initial_transform.hive_server_task manual__2024-11-05T21:02:25.593672+00:00 [queued]>
[2024-11-05T21:02:29.951+0000] {taskinstance.py:1361} INFO - Starting attempt 1 of 1
[2024-11-05T21:02:29.961+0000] {taskinstance.py:1382} INFO - Executing <Task(SSHOperator): hive_server_task> on 2024-11-05 21:02:25.593672+00:00
[2024-11-05T21:02:29.970+0000] {standard_task_runner.py:57} INFO - Started process 738 to run task
[2024-11-05T21:02:29.973+0000] {standard_task_runner.py:84} INFO - Running: ['***', 'tasks', 'run', 'initial_transform', 'hive_server_task', 'manual__2024-11-05T21:02:25.593672+00:00', '--job-id', '23', '--raw', '--subdir', 'DAGS_FOLDER/initial_transform.py', '--cfg-path', '/tmp/tmpkb5x6vgc']
[2024-11-05T21:02:29.974+0000] {standard_task_runner.py:85} INFO - Job 23: Subtask hive_server_task
[2024-11-05T21:02:30.028+0000] {task_command.py:416} INFO - Running <TaskInstance: initial_transform.hive_server_task manual__2024-11-05T21:02:25.593672+00:00 [running]> on host c5156f201d33
[2024-11-05T21:02:30.116+0000] {taskinstance.py:1662} INFO - Exporting env vars: AIRFLOW_CTX_DAG_OWNER='***' AIRFLOW_CTX_DAG_ID='initial_transform' AIRFLOW_CTX_TASK_ID='hive_server_task' AIRFLOW_CTX_EXECUTION_DATE='2024-11-05T21:02:25.593672+00:00' AIRFLOW_CTX_TRY_NUMBER='1' AIRFLOW_CTX_DAG_RUN_ID='manual__2024-11-05T21:02:25.593672+00:00'
[2024-11-05T21:02:30.117+0000] {ssh.py:152} INFO - Creating ssh_client
[2024-11-05T21:02:30.117+0000] {ssh.py:300} WARNING - No Host Key Verification. This won't protect against Man-In-The-Middle attacks
[2024-11-05T21:02:30.119+0000] {ssh.py:342} INFO - Failed to connect. Sleeping before retry attempt 1
[2024-11-05T21:02:34.676+0000] {ssh.py:342} INFO - Failed to connect. Sleeping before retry attempt 2
[2024-11-05T21:02:37.930+0000] {taskinstance.py:1937} ERROR - Task failed with exception
Traceback (most recent call last):
  File "/home/airflow/.local/lib/python3.11/site-packages/airflow/providers/ssh/operators/ssh.py", line 190, in execute
    with self.get_ssh_client() as ssh_client:
         ^^^^^^^^^^^^^^^^^^^^^
  File "/home/airflow/.local/lib/python3.11/site-packages/airflow/providers/ssh/operators/ssh.py", line 153, in get_ssh_client
    return self.hook.get_conn()
           ^^^^^^^^^^^^^^^^^^^^
  File "/home/airflow/.local/lib/python3.11/site-packages/airflow/providers/ssh/hooks/ssh.py", line 346, in get_conn
    for attempt in Retrying(
  File "/home/airflow/.local/lib/python3.11/site-packages/tenacity/__init__.py", line 347, in __iter__
    do = self.iter(retry_state=retry_state)
         ^^^^^^^^^^^^^^^^^^^^^^^^^^^^^^^^^^
  File "/home/airflow/.local/lib/python3.11/site-packages/tenacity/__init__.py", line 325, in iter
    raise retry_exc.reraise()
          ^^^^^^^^^^^^^^^^^^^
  File "/home/airflow/.local/lib/python3.11/site-packages/tenacity/__init__.py", line 158, in reraise
    raise self.last_attempt.result()
          ^^^^^^^^^^^^^^^^^^^^^^^^^^
  File "/usr/local/lib/python3.11/concurrent/futures/_base.py", line 449, in result
    return self.__get_result()
           ^^^^^^^^^^^^^^^^^^^
  File "/usr/local/lib/python3.11/concurrent/futures/_base.py", line 401, in __get_result
    raise self._exception
  File "/home/airflow/.local/lib/python3.11/site-packages/airflow/providers/ssh/hooks/ssh.py", line 353, in get_conn
    client.connect(**connect_kwargs)
  File "/home/airflow/.local/lib/python3.11/site-packages/paramiko/client.py", line 409, in connect
    raise NoValidConnectionsError(errors)
paramiko.ssh_exception.NoValidConnectionsError: [Errno None] Unable to connect to port 22 on 172.18.0.11
[2024-11-05T21:02:37.947+0000] {taskinstance.py:1400} INFO - Marking task as FAILED. dag_id=initial_transform, task_id=hive_server_task, execution_date=20241105T210225, start_date=20241105T210229, end_date=20241105T210237
[2024-11-05T21:02:37.957+0000] {standard_task_runner.py:104} ERROR - Failed to execute job 23 for task hive_server_task ([Errno None] Unable to connect to port 22 on 172.18.0.11; 738)
[2024-11-05T21:02:37.969+0000] {local_task_job_runner.py:228} INFO - Task exited with return code 1
[2024-11-05T21:02:37.987+0000] {taskinstance.py:2778} INFO - 0 downstream tasks scheduled from follow-on schedule check
