[2024-11-05T19:44:15.478+0000] {taskinstance.py:1159} INFO - Dependencies all met for dep_context=non-requeueable deps ti=<TaskInstance: load_initial_data.load_data manual__2024-11-05T19:44:14.090358+00:00 [queued]>
[2024-11-05T19:44:15.493+0000] {taskinstance.py:1159} INFO - Dependencies all met for dep_context=requeueable deps ti=<TaskInstance: load_initial_data.load_data manual__2024-11-05T19:44:14.090358+00:00 [queued]>
[2024-11-05T19:44:15.494+0000] {taskinstance.py:1361} INFO - Starting attempt 1 of 1
[2024-11-05T19:44:15.513+0000] {taskinstance.py:1382} INFO - Executing <Task(SSHOperator): load_data> on 2024-11-05 19:44:14.090358+00:00
[2024-11-05T19:44:15.527+0000] {standard_task_runner.py:57} INFO - Started process 95 to run task
[2024-11-05T19:44:15.531+0000] {standard_task_runner.py:84} INFO - Running: ['***', 'tasks', 'run', 'load_initial_data', 'load_data', 'manual__2024-11-05T19:44:14.090358+00:00', '--job-id', '3', '--raw', '--subdir', 'DAGS_FOLDER/load_initial_data.py', '--cfg-path', '/tmp/tmpwn0mld08']
[2024-11-05T19:44:15.532+0000] {standard_task_runner.py:85} INFO - Job 3: Subtask load_data
[2024-11-05T19:44:15.602+0000] {task_command.py:416} INFO - Running <TaskInstance: load_initial_data.load_data manual__2024-11-05T19:44:14.090358+00:00 [running]> on host 02af4744f5fd
[2024-11-05T19:44:15.714+0000] {taskinstance.py:1662} INFO - Exporting env vars: AIRFLOW_CTX_DAG_OWNER='***' AIRFLOW_CTX_DAG_ID='load_initial_data' AIRFLOW_CTX_TASK_ID='load_data' AIRFLOW_CTX_EXECUTION_DATE='2024-11-05T19:44:14.090358+00:00' AIRFLOW_CTX_TRY_NUMBER='1' AIRFLOW_CTX_DAG_RUN_ID='manual__2024-11-05T19:44:14.090358+00:00'
[2024-11-05T19:44:15.716+0000] {ssh.py:152} INFO - Creating ssh_client
[2024-11-05T19:44:15.717+0000] {ssh.py:300} WARNING - No Host Key Verification. This won't protect against Man-In-The-Middle attacks
[2024-11-05T19:44:15.736+0000] {transport.py:1893} INFO - Connected (version 2.0, client OpenSSH_7.4p1)
[2024-11-05T19:44:15.810+0000] {transport.py:1893} INFO - Authentication (password) successful!
[2024-11-05T19:44:15.812+0000] {ssh.py:478} INFO - Running command: /opt/hadoop-3.2.1/bin/hdfs dfs -mkdir /data && /opt/hadoop-3.2.1/bin/hdfs dfs -copyFromLocal /data/sprogrami2016.csv /data && /opt/hadoop-3.2.1/bin/hdfs dfs -ls
[2024-11-05T19:44:19.525+0000] {ssh.py:529} WARNING - 2024-11-05 19:44:19,523 INFO sasl.SaslDataTransferClient: SASL encryption trust check: localHostTrusted = false, remoteHostTrusted = false
[2024-11-05T19:44:21.233+0000] {ssh.py:529} WARNING - ls: `.': No such file or directory
[2024-11-05T19:44:21.718+0000] {taskinstance.py:1937} ERROR - Task failed with exception
Traceback (most recent call last):
  File "/home/airflow/.local/lib/python3.11/site-packages/airflow/providers/ssh/operators/ssh.py", line 191, in execute
    result = self.run_ssh_client_command(ssh_client, self.command, context=context)
             ^^^^^^^^^^^^^^^^^^^^^^^^^^^^^^^^^^^^^^^^^^^^^^^^^^^^^^^^^^^^^^^^^^^^^^
  File "/home/airflow/.local/lib/python3.11/site-packages/airflow/providers/ssh/operators/ssh.py", line 179, in run_ssh_client_command
    self.raise_for_status(exit_status, agg_stderr, context=context)
  File "/home/airflow/.local/lib/python3.11/site-packages/airflow/providers/ssh/operators/ssh.py", line 173, in raise_for_status
    raise AirflowException(f"SSH operator error: exit status = {exit_status}")
airflow.exceptions.AirflowException: SSH operator error: exit status = 1
[2024-11-05T19:44:21.722+0000] {taskinstance.py:1400} INFO - Marking task as FAILED. dag_id=load_initial_data, task_id=load_data, execution_date=20241105T194414, start_date=20241105T194415, end_date=20241105T194421
[2024-11-05T19:44:21.736+0000] {standard_task_runner.py:104} ERROR - Failed to execute job 3 for task load_data (SSH operator error: exit status = 1; 95)
[2024-11-05T19:44:21.767+0000] {local_task_job_runner.py:228} INFO - Task exited with return code 1
[2024-11-05T19:44:21.786+0000] {taskinstance.py:2778} INFO - 0 downstream tasks scheduled from follow-on schedule check
