[2024-11-05T20:10:17.581+0000] {taskinstance.py:1159} INFO - Dependencies all met for dep_context=non-requeueable deps ti=<TaskInstance: initial_transform.transform manual__2024-11-05T20:10:16.655214+00:00 [queued]>
[2024-11-05T20:10:17.592+0000] {taskinstance.py:1159} INFO - Dependencies all met for dep_context=requeueable deps ti=<TaskInstance: initial_transform.transform manual__2024-11-05T20:10:16.655214+00:00 [queued]>
[2024-11-05T20:10:17.592+0000] {taskinstance.py:1361} INFO - Starting attempt 1 of 1
[2024-11-05T20:10:17.613+0000] {taskinstance.py:1382} INFO - Executing <Task(_PythonDecoratedOperator): transform> on 2024-11-05 20:10:16.655214+00:00
[2024-11-05T20:10:17.631+0000] {standard_task_runner.py:57} INFO - Started process 464 to run task
[2024-11-05T20:10:17.636+0000] {standard_task_runner.py:84} INFO - Running: ['***', 'tasks', 'run', 'initial_transform', 'transform', 'manual__2024-11-05T20:10:16.655214+00:00', '--job-id', '13', '--raw', '--subdir', 'DAGS_FOLDER/initial_transform.py', '--cfg-path', '/tmp/tmptcx4u_7q']
[2024-11-05T20:10:17.638+0000] {standard_task_runner.py:85} INFO - Job 13: Subtask transform
[2024-11-05T20:10:17.709+0000] {task_command.py:416} INFO - Running <TaskInstance: initial_transform.transform manual__2024-11-05T20:10:16.655214+00:00 [running]> on host 02af4744f5fd
[2024-11-05T20:10:17.799+0000] {taskinstance.py:1662} INFO - Exporting env vars: AIRFLOW_CTX_DAG_OWNER='***' AIRFLOW_CTX_DAG_ID='initial_transform' AIRFLOW_CTX_TASK_ID='transform' AIRFLOW_CTX_EXECUTION_DATE='2024-11-05T20:10:16.655214+00:00' AIRFLOW_CTX_TRY_NUMBER='1' AIRFLOW_CTX_DAG_RUN_ID='manual__2024-11-05T20:10:16.655214+00:00'
[2024-11-05T20:10:17.814+0000] {base.py:73} INFO - Using connection ID 'HIVE_CONNECTION' for task execution.
[2024-11-05T20:10:17.827+0000] {TSocket.py:133} ERROR - failed to resolve sockaddr for jdbc:hive2://hive-server:10000
Traceback (most recent call last):
  File "/home/airflow/.local/lib/python3.11/site-packages/thrift/transport/TSocket.py", line 130, in open
    addrs = self._resolveAddr()
            ^^^^^^^^^^^^^^^^^^^
  File "/home/airflow/.local/lib/python3.11/site-packages/thrift/transport/TSocket.py", line 37, in _resolveAddr
    return socket.getaddrinfo(self.host,
           ^^^^^^^^^^^^^^^^^^^^^^^^^^^^^
  File "/usr/local/lib/python3.11/socket.py", line 962, in getaddrinfo
    for res in _socket.getaddrinfo(host, port, family, type, proto, flags):
               ^^^^^^^^^^^^^^^^^^^^^^^^^^^^^^^^^^^^^^^^^^^^^^^^^^^^^^^^^^^
socket.gaierror: [Errno -2] Name or service not known
[2024-11-05T20:10:17.828+0000] {taskinstance.py:1937} ERROR - Task failed with exception
Traceback (most recent call last):
  File "/home/airflow/.local/lib/python3.11/site-packages/thrift/transport/TSocket.py", line 130, in open
    addrs = self._resolveAddr()
            ^^^^^^^^^^^^^^^^^^^
  File "/home/airflow/.local/lib/python3.11/site-packages/thrift/transport/TSocket.py", line 37, in _resolveAddr
    return socket.getaddrinfo(self.host,
           ^^^^^^^^^^^^^^^^^^^^^^^^^^^^^
  File "/usr/local/lib/python3.11/socket.py", line 962, in getaddrinfo
    for res in _socket.getaddrinfo(host, port, family, type, proto, flags):
               ^^^^^^^^^^^^^^^^^^^^^^^^^^^^^^^^^^^^^^^^^^^^^^^^^^^^^^^^^^^
socket.gaierror: [Errno -2] Name or service not known

During handling of the above exception, another exception occurred:

Traceback (most recent call last):
  File "/home/airflow/.local/lib/python3.11/site-packages/airflow/decorators/base.py", line 221, in execute
    return_value = super().execute(context)
                   ^^^^^^^^^^^^^^^^^^^^^^^^
  File "/home/airflow/.local/lib/python3.11/site-packages/airflow/operators/python.py", line 192, in execute
    return_value = self.execute_callable()
                   ^^^^^^^^^^^^^^^^^^^^^^^
  File "/home/airflow/.local/lib/python3.11/site-packages/airflow/operators/python.py", line 209, in execute_callable
    return self.python_callable(*self.op_args, **self.op_kwargs)
           ^^^^^^^^^^^^^^^^^^^^^^^^^^^^^^^^^^^^^^^^^^^^^^^^^^^^^
  File "/opt/airflow/dags/initial_transform.py", line 21, in transform
    res = hive_hook.get_records('select * from invites')
          ^^^^^^^^^^^^^^^^^^^^^^^^^^^^^^^^^^^^^^^^^^^^^^
  File "/home/airflow/.local/lib/python3.11/site-packages/airflow/providers/apache/hive/hooks/hive.py", line 1016, in get_records
    return self.get_results(sql, schema=schema, hive_conf=parameters)["data"]
           ^^^^^^^^^^^^^^^^^^^^^^^^^^^^^^^^^^^^^^^^^^^^^^^^^^^^^^^^^^
  File "/home/airflow/.local/lib/python3.11/site-packages/airflow/providers/apache/hive/hooks/hive.py", line 946, in get_results
    header = next(results_iter)
             ^^^^^^^^^^^^^^^^^^
  File "/home/airflow/.local/lib/python3.11/site-packages/airflow/providers/apache/hive/hooks/hive.py", line 891, in _get_results
    with contextlib.closing(self.get_conn(schema)) as conn, contextlib.closing(conn.cursor()) as cur:
                            ^^^^^^^^^^^^^^^^^^^^^
  File "/home/airflow/.local/lib/python3.11/site-packages/airflow/providers/apache/hive/hooks/hive.py", line 869, in get_conn
    return connect(
           ^^^^^^^^
  File "/home/airflow/.local/lib/python3.11/site-packages/pyhive/hive.py", line 143, in connect
    return Connection(*args, **kwargs)
           ^^^^^^^^^^^^^^^^^^^^^^^^^^^
  File "/home/airflow/.local/lib/python3.11/site-packages/pyhive/hive.py", line 269, in __init__
    self._transport.open()
  File "/home/airflow/.local/lib/python3.11/site-packages/thrift_sasl/__init__.py", line 74, in open
    self._trans.open()
  File "/home/airflow/.local/lib/python3.11/site-packages/thrift/transport/TSocket.py", line 134, in open
    raise TTransportException(type=TTransportException.NOT_OPEN, message=msg, inner=gai)
thrift.transport.TTransport.TTransportException: failed to resolve sockaddr for jdbc:hive2://hive-server:10000
[2024-11-05T20:10:17.840+0000] {taskinstance.py:1400} INFO - Marking task as FAILED. dag_id=initial_transform, task_id=transform, execution_date=20241105T201016, start_date=20241105T201017, end_date=20241105T201017
[2024-11-05T20:10:17.850+0000] {standard_task_runner.py:104} ERROR - Failed to execute job 13 for task transform (failed to resolve sockaddr for jdbc:hive2://hive-server:10000; 464)
[2024-11-05T20:10:17.888+0000] {local_task_job_runner.py:228} INFO - Task exited with return code 1
[2024-11-05T20:10:17.910+0000] {taskinstance.py:2778} INFO - 0 downstream tasks scheduled from follow-on schedule check
